Workbook

Sheet Throughput Statistics
A1: Queenstown International Airport - GlideView Reports
A2: Throughput Statistics Week Ending Sunday, 25 October 2026
A4: Throughput
A5: Check-in
B6: Bags Count
A7: DESK01 | B7: 923
A8: DESK02 | B8: 1304
A9: DESK03 | B9: 1950
A10: DESK04 | B10: 2368
A11: DESK05 | B11: 2070
A12: DESK06 | B12: 118
A13: DESK07 | B13: 582
A14: DESK08 | B14: 846
A15: DESK09 | B15: 171
A16: DESK10 | B16: 635
A17: DESK11 | B17: 771
A18: DESK12 | B18: 691
... A28: DESK22 | B28: 459
A29: OB1
B30: Bags Count
A31: T101 | B31: 20573
A32: T114 | B32: 20551
A33: MU1_RECIRC | B33: 19230
A34: OS1
B35: Bags Count
A36: OS104 | B36: 1582

Sheet Maintenance Statistics
A1: Queenstown International Airport - GlideView Reports
A2: Maintenance Statistics Week Ending Sunday, 25 October 2026
A4: Check-in Conveyor
A5: OB1
B6: Check-in Motor Starts
A7: C101 | B7: 0
A8: C102 | B8: 0
A9: C103 | B9: 0
A10: C104 | B10: 0
A11: C105 | B11: 0
A12: C106 | B12: 0
A13: C107 | B13: 0
A14: C108 | B14: 0
A15: C109 | B15: 0
A16: C110 | B16: 0
A17: C111 | B17: 0
A18: C112 | B18: 0
... A47: C144 | B47: 0
A49: Conveyor
A50: OB1
B51: Conveyor Motor Hours
A52: C133 | B52: 10.53
A53: C134 | B53: 10.55
A54: C135 | B54: 8.75
A55: C146 | B55: 10.51
A56: MU1 | B56: 10.5
A57: T101 | B57: 6.38
A58: T102 | B58: 7.27
A59: T103 | B59: 7.25
A60: T104 | B60: 6.16
A61: T105 | B61: 5.76
A62: T106 | B62: 5.9
A63: T107 | B63: 6.14
... A79: T110A | B79: 7.21
A80: OS1
B81: Conveyor Motor Hours
A82: OS101 | B82: 5.22
A83: OS103 | B83: 92.17
A84: OS104 | B84: 14.53
A85: OS105 | B85: 8.06
...

Sheet Security Screening Statistics
A1: Queenstown International Airport - GlideView Reports
A2: Security Screening Statistics Week Ending Sunday, 25 October 2026
A4: Level 1 EDS Decisions
A5: OB1
B6: L1 Clear Bag Count | C6: L1 Reject Bag Count | D6: L1 No Scan Count | E6: L1 Timeout Count
A7: T109XR | B7: 12412 | C7: 7240 | D7: 55 | E7: 0
A9: Level 2 EDS Decisions
A10: OB1
B11: L2 Clear Count | C11: L2 Reject Count | D11: L2 Timeout Count
A12: T109XR | B12: 6574 | C12: 507 | D12: 157

Sheet Tracking Statistics
A1: Queenstown International Airport - GlideView Reports
A2: Tracking Statistics Week Ending Sunday, 25 October 2026
A4: Zone
A5: OB1
B6: Tracked Bag Count | C6: Lost Bag Count
A7: T109PC | B7: 0 | C7: 0
A8: T110PC | B8: 19652 | C8: 35
A9: T111PC | B9: 19601 | C9: 1
A10: T112PC | B10: 19629 | C10: 1
A11: T1DV1PD | B11: 19633 | C11: 11
A12: T1DV1PU | B12: 18929 | C12: 2
A13: T110APC | B13: 19624 | C13: 18

Sheet Plough Statistics
A1: Queenstown International Airport - GlideView Reports
A2: Plough Statistics Week Ending Sunday, 25 October 2026
A4: Plough
A5: OB1
B6: Barcode Label Count | C6: Pushed Bag Count | D6: Not Pushed Bag Count | E6: Watch-dog timeout Count | F6: Clear Count | G6: Reject Count | H6: Waiting Count | I6: Failed on wait Count | J6: Removed Count | K6: Wait then cleared Count | L6: L2 Failed on PE Count | M6: Mistrack Count | N6: No scan on arrival Count | O6: Time out on arrival Count | P6: No scasn while waiting Count | Q6: Forced misstracked Count | R6: Random Count | S6: Text Label Count
A7: T1DV1 | B7: 661 | C7: 727 | D7: 18931 | E7: 0 | F7: 43676 | G7: 630 | H7: 3309 | I7: 454 | J7: 86 | K7: 2329 | L7: 335 | M7: 255 | N7: 79 | O7: 13 | P7: 0 | Q7: 0 | R7: 0 | S7: 135

Sheet Fault Table
A1: Queenstown International Airport - GlideView Reports
A2: Fault Table Week Ending Sunday, 25 October 2026
B4: ABD General Fault | C4: ABD Intrusion Fault | D4: ABD Not Available Fault | E4: Bag Jam Fault | F4: Bag Timeout Fault | G4: Bag Under Door PE Sensor Fault | H4: BMS Fire Fault | I4: BMU OB1 Full | J4: Conveyor Cascade PE Fault | K4: Conveyor Motor Feedback Fault | L4: Conveyor Motor Overload Fault | M4: Decision PE Sensor Fault | N4: Desk has a Fault | O4: Desk Isolator Fault | P4: Dieback Status | Q4: DNET_NODE_10_FAULT | R4: DNET_NODE_11_FAULT | S4: DNET_NODE_12_FAULT | T4: DNET_NODE_13_FAULT | U4: DNET_NODE_14_FAULT | V4: DNET_NODE_15_FAULT | W4: DNET_NODE_1_FAULT | X4: DNET_NODE_2_FAULT | Y4: DNET_NODE_3_FAULT | Z4: DNET_NODE_4_FAULT | AA4: DNET_NODE_5_FAULT | AB4: DNET_NODE_6_FAULT | AC4: DNET_NODE_7_FAULT | AD4: DNET_NODE_8_FAULT | AE4: DNET_NODE_9_FAULT | AF4: Door BMS Fire Fault | AG4: Door Estop Critical Fault | AH4: Door Limit Switch Fault | AI4: Door Motor Fault | AJ4: Door Motor Isolator | AK4: Door Override Active | AL4: Door PXC | AM4: Door PXO | AN4: Door Safety Edge | AO4: Emergency Stop / Critical Fault | AP4: Emergency Stop Fault | AQ4: Emergency Stop Relay Fault | AR4: Fuse Fault | AS4: General Fault | AT4: I_O Fault | AU4: Induct Motor Feedback Fault | AV4: Induct Motor Overload Fault | AW4: Induct PE Sensor Fault | AX4: Intrusion Fault | AY4: Kupe PLC Comms to Airflow ME 1 Fault | AZ4: Kupe PLC Comms to Airflow ME 2 Fault | BA4: Kupe PLC Comms to Airflow ME 3 Fault | BB4: Kupe PLC Comms to Airflow ME 4 Fault | BC4: Kupe PLC Comms to MOXA Scale 1 Fault | BD4: Kupe PLC Comms to MOXA Scale 2 Fault | BE4: Kupe PLC Comms to MOXA Scale 3 Fault | BF4: Kupe PLC Comms to MOXA Scale 4 Fault | BG4: Machine Fault | BH4: Motor Fault | BI4: Motor Feedback Fault | BJ4: Motor Isolator Fault | BK4: Not Available Fault | BL4: Not Ready Fault | BM4: Overheight Fault | BN4: Override Active | BO4: PE1 PE Sensor Fault | BP4: PLC Battery Fault | BQ4: PLC Battery Fault | BR4: PLC Comms Fault | BS4: PLC I/O Fault | BT4: Plough Arm Motor Feedback Fault | BU4: Plough Arm Motor Overload Fault | BV4: Plough Arm Motor/Actuator Isolator Fault | BW4: Plough Belt Motor Feedback Fault | BX4: Plough Belt Motor Isolator Fault | BY4: Plough Belt Motor Overload Fault | BZ4: Plough Failsafe Alarm | CA4: Plough Jam Fault | CB4: Plough Motor Feedback Fault | CC4: Plough Not Extended Fault | CD4: Plough Not Retracted Fault | CE4: Plough PE Jam Fault | CF4: Plough Proximity Sensor Fault | CG4: Pulse Wheel Fault | CH4: Scale Motor Feedback Fault | CI4: Scale Motor Overload Fault | CJ4: Scale PE Sensor Fault | CK4: Serial Communications Fault | CL4: Update PE Fault | CM4: Update PE Sensor Fault | CN4: UPS Fault | CO4: Voltage Monitor Fault | CP4: TOTAL
A5: C004Q1_SF | B5: 0 | C5: 0 | D5: 0 | E5: 0 | F5: 0 | G5: 0 | H5: 0 | I5: 0 | J5: 0 | K5: 0 | L5: 0 | M5: 0 | N5: 0 | O5: 0 | P5: 0 | Q5: 0 | R5: 0 | S5: 0 | T5: 0 | U5: 0 | V5: 0 | W5: 0 | X5: 0 | Y5: 0 | Z5: 0 | AA5: 0 | AB5: 0 | AC5: 0 | AD5: 0 | AE5: 0 | AF5: 0 | AG5: 0 | AH5: 0 | AI5: 0 | AJ5: 0 | AK5: 0 | AL5: 0 | AM5: 0 | AN5: 0 | AO5: 0 | AP5: 0 | AQ5: 0 | AR5: 0 | AS5: 0 | AT5: 0 | AU5: 0 | AV5: 0 | AW5: 0 | AX5: 0 | AY5: 0 | AZ5: 0 | BA5: 0 | BB5: 0 | BC5: 0 | BD5: 0 | BE5: 0 | BF5: 0 | BG5: 0 | BH5: 0 | BI5: 0 | BJ5: 0 | BK5: 0 | BL5: 0 | BM5: 0 | BN5: 0 | BO5: 0 | BP5: 0 | BQ5: 0 | BR5: 0 | BS5: 0 | BT5: 0 | BU5: 0 | BV5: 0 | BW5: 0 | BX5: 0 | BY5: 0 | BZ5: 0 | CA5: 0 | CB5: 0 | CC5: 0 | CD5: 0 | CE5: 0 | CF5: 0 | CG5: 0 | CH5: 0 | CI5: 0 | CJ5: 0 | CK5: 0 | CL5: 0 | CM5: 0 | CN5: 0 | CO5: 0 | CP5: =SUM(B5:CO5) -> 0
A6: C004Q2_SF | B6: 0 | C6: 0 | D6: 0 | E6: 0 | F6: 0 | G6: 0 | H6: 0 | I6: 0 | J6: 0 | K6: 0 | L6: 0 | M6: 0 | N6: 0 | O6: 0 | P6: 0 | Q6: 0 | R6: 0 | S6: 0 | T6: 0 | U6: 0 | V6: 0 | W6: 0 | X6: 0 | Y6: 0 | Z6: 0 | AA6: 0 | AB6: 0 | AC6: 0 | AD6: 0 | AE6: 0 | AF6: 0 | AG6: 0 | AH6: 0 | AI6: 0 | AJ6: 0 | AK6: 0 | AL6: 0 | AM6: 0 | AN6: 0 | AO6: 0 | AP6: 0 | AQ6: 0 | AR6: 0 | AS6: 0 | AT6: 0 | AU6: 0 | AV6: 0 | AW6: 0 | AX6: 0 | AY6: 0 | AZ6: 0 | BA6: 0 | BB6: 0 | BC6: 0 | BD6: 0 | BE6: 0 | BF6: 0 | BG6: 0 | BH6: 0 | BI6: 0 | BJ6: 0 | BK6: 0 | BL6: 0 | BM6: 0 | BN6: 0 | BO6: 0 | BP6: 0 | BQ6: 0 | BR6: 0 | BS6: 0 | BT6: 0 | BU6: 0 | BV6: 0 | BW6: 0 | BX6: 0 | BY6: 0 | BZ6: 0 | CA6: 0 | CB6: 0 | CC6: 0 | CD6: 0 | CE6: 0 | CF6: 0 | CG6: 0 | CH6: 0 | CI6: 0 | CJ6: 0 | CK6: 0 | CL6: 0 | CM6: 0 | CN6: 0 | CO6: 0 | CP6: =SUM(B6:CO6) -> 0
A7: C004Q3_SF | B7: 0 | C7: 0 | D7: 0 | E7: 0 | F7: 0 | G7: 0 | H7: 0 | I7: 0 | J7: 0 | K7: 0 | L7: 0 | M7: 0 | N7: 0 | O7: 0 | P7: 0 | Q7: 0 | R7: 0 | S7: 0 | T7: 0 | U7: 0 | V7: 0 | W7: 0 | X7: 0 | Y7: 0 | Z7: 0 | AA7: 0 | AB7: 0 | AC7: 0 | AD7: 0 | AE7: 0 | AF7: 0 | AG7: 0 | AH7: 0 | AI7: 0 | AJ7: 0 | AK7: 0 | AL7: 0 | AM7: 0 | AN7: 0 | AO7: 0 | AP7: 0 | AQ7: 0 | AR7: 0 | AS7: 0 | AT7: 0 | AU7: 0 | AV7: 0 | AW7: 0 | AX7: 0 | AY7: 0 | AZ7: 0 | BA7: 0 | BB7: 0 | BC7: 0 | BD7: 0 | BE7: 0 | BF7: 0 | BG7: 0 | BH7: 0 | BI7: 0 | BJ7: 0 | BK7: 0 | BL7: 0 | BM7: 0 | BN7: 0 | BO7: 0 | BP7: 0 | BQ7: 0 | BR7: 0 | BS7: 0 | BT7: 0 | BU7: 0 | BV7: 0 | BW7: 0 | BX7: 0 | BY7: 0 | BZ7: 0 | CA7: 0 | CB7: 0 | CC7: 0 | CD7: 0 | CE7: 0 | CF7: 0 | CG7: 0 | CH7: 0 | CI7: 0 | CJ7: 0 | CK7: 0 | CL7: 0 | CM7: 0 | CN7: 0 | CO7: 0 | CP7: =SUM(B7:CO7) -> 0
A8: C004Q4_SF | B8: 0 | C8: 0 | D8: 0 | E8: 0 | F8: 0 | G8: 0 | H8: 0 | I8: 0 | J8: 0 | K8: 0 | L8: 0 | M8: 0 | N8: 0 | O8: 0 | P8: 0 | Q8: 0 | R8: 0 | S8: 0 | T8: 0 | U8: 0 | V8: 0 | W8: 0 | X8: 0 | Y8: 0 | Z8: 0 | AA8: 0 | AB8: 0 | AC8: 0 | AD8: 0 | AE8: 0 | AF8: 0 | AG8: 0 | AH8: 0 | AI8: 0 | AJ8: 0 | AK8: 0 | AL8: 0 | AM8: 0 | AN8: 0 | AO8: 0 | AP8: 0 | AQ8: 0 | AR8: 0 | AS8: 0 | AT8: 0 | AU8: 0 | AV8: 0 | AW8: 0 | AX8: 0 | AY8: 0 | AZ8: 0 | BA8: 0 | BB8: 0 | BC8: 0 | BD8: 0 | BE8: 0 | BF8: 0 | BG8: 0 | BH8: 0 | BI8: 0 | BJ8: 0 | BK8: 0 | BL8: 0 | BM8: 0 | BN8: 0 | BO8: 0 | BP8: 0 | BQ8: 0 | BR8: 0 | BS8: 0 | BT8: 0 | BU8: 0 | BV8: 0 | BW8: 0 | BX8: 0 | BY8: 0 | BZ8: 0 | CA8: 0 | CB8: 0 | CC8: 0 | CD8: 0 | CE8: 0 | CF8: 0 | CG8: 0 | CH8: 0 | CI8: 0 | CJ8: 0 | CK8: 0 | CL8: 0 | CM8: 0 | CN8: 0 | CO8: 0 | CP8: =SUM(B8:CO8) -> 0
A9: C101 | B9: 0 | C9: 0 | D9: 0 | E9: 0 | F9: 0 | G9: 0 | H9: 0 | I9: 0 | J9: 0 | K9: 0 | L9: 0 | M9: 0 | N9: 0 | O9: 0 | P9: 0 | Q9: 0 | R9: 0 | S9: 0 | T9: 0 | U9: 0 | V9: 0 | W9: 0 | X9: 0 | Y9: 0 | Z9: 0 | AA9: 0 | AB9: 0 | AC9: 0 | AD9: 0 | AE9: 0 | AF9: 0 | AG9: 0 | AH9: 0 | AI9: 0 | AJ9: 0 | AK9: 0 | AL9: 0 | AM9: 0 | AN9: 0 | AO9: 0 | AP9: 0 | AQ9: 0 | AR9: 0 | AS9: 0 | AT9: 0 | AU9: 0 | AV9: 0 | AW9: 0 | AX9: 0 | AY9: 0 | AZ9: 0 | BA9: 0 | BB9: 0 | BC9: 0 | BD9: 0 | BE9: 0 | BF9: 0 | BG9: 0 | BH9: 0 | BI9: 0 | BJ9: 0 | BK9: 0 | BL9: 0 | BM9: 0 | BN9: 0 | BO9: 0 | BP9: 0 | BQ9: 0 | BR9: 0 | BS9: 0 | BT9: 0 | BU9: 0 | BV9: 0 | BW9: 0 | BX9: 0 | BY9: 0 | BZ9: 0 | CA9: 0 | CB9: 0 | CC9: 0 | CD9: 0 | CE9: 0 | CF9: 0 | CG9: 0 | CH9: 0 | CI9: 0 | CJ9: 0 | CK9: 0 | CL9: 1 | CM9: 0 | CN9: 0 | CO9: 0 | CP9: =SUM(B9:CO9) -> 1
A10: C101ES | B10: 0 | C10: 0 | D10: 0 | E10: 0 | F10: 0 | G10: 0 | H10: 0 | I10: 0 | J10: 0 | K10: 0 | L10: 0 | M10: 0 | N10: 0 | O10: 0 | P10: 0 | Q10: 0 | R10: 0 | S10: 0 | T10: 0 | U10: 0 | V10: 0 | W10: 0 | X10: 0 | Y10: 0 | Z10: 0 | AA10: 0 | AB10: 0 | AC10: 0 | AD10: 0 | AE10: 0 | AF10: 0 | AG10: 0 | AH10: 0 | AI10: 0 | AJ10: 0 | AK10: 0 | AL10: 0 | AM10: 0 | AN10: 0 | AO10: 0 | AP10: 0 | AQ10: 0 | AR10: 0 | AS10: 0 | AT10: 0 | AU10: 0 | AV10: 0 | AW10: 0 | AX10: 0 | AY10: 0 | AZ10: 0 | BA10: 0 | BB10: 0 | BC10: 0 | BD10: 0 | BE10: 0 | BF10: 0 | BG10: 0 | BH10: 0 | BI10: 0 | BJ10: 0 | BK10: 0 | BL10: 0 | BM10: 0 | BN10: 0 | BO10: 0 | BP10: 0 | BQ10: 0 | BR10: 0 | BS10: 0 | BT10: 0 | BU10: 0 | BV10: 0 | BW10: 0 | BX10: 0 | BY10: 0 | BZ10: 0 | CA10: 0 | CB10: 0 | CC10: 0 | CD10: 0 | CE10: 0 | CF10: 0 | CG10: 0 | CH10: 0 | CI10: 0 | CJ10: 0 | CK10: 0 | CL10: 0 | CM10: 0 | CN10: 0 | CO10: 0 | CP10: =SUM(B10:CO10) -> 0
A11: C102 | B11: 0 | C11: 0 | D11: 0 | E11: 0 | F11: 0 | G11: 0 | H11: 0 | I11: 0 | J11: 0 | K11: 0 | L11: 0 | M11: 0 | N11: 0 | O11: 0 | P11: 0 | Q11: 0 | R11: 0 | S11: 0 | T11: 0 | U11: 0 | V11: 0 | W11: 0 | X11: 0 | Y11: 0 | Z11: 0 | AA11: 0 | AB11: 0 | AC11: 0 | AD11: 0 | AE11: 0 | AF11: 0 | AG11: 0 | AH11: 0 | AI11: 0 | AJ11: 0 | AK11: 0 | AL11: 0 | AM11: 0 | AN11: 0 | AO11: 0 | AP11: 0 | AQ11: 0 | AR11: 0 | AS11: 0 | AT11: 0 | AU11: 0 | AV11: 0 | AW11: 0 | AX11: 0 | AY11: 0 | AZ11: 0 | BA11: 0 | BB11: 0 | BC11: 0 | BD11: 0 | BE11: 0 | BF11: 0 | BG11: 0 | BH11: 0 | BI11: 0 | BJ11: 0 | BK11: 0 | BL11: 0 | BM11: 0 | BN11: 0 | BO11: 0 | BP11: 0 | BQ11: 0 | BR11: 0 | BS11: 0 | BT11: 0 | BU11: 0 | BV11: 0 | BW11: 0 | BX11: 0 | BY11: 0 | BZ11: 0 | CA11: 0 | CB11: 0 | CC11: 0 | CD11: 0 | CE11: 0 | CF11: 0 | CG11: 0 | CH11: 0 | CI11: 0 | CJ11: 0 | CK11: 0 | CL11: 0 | CM11: 0 | CN11: 0 | CO11: 0 | CP11: =SUM(B11:CO11) -> 0
A12: C103 | B12: 0 | C12: 0 | D12: 0 | E12: 0 | F12: 0 | G12: 0 | H12: 0 | I12: 0 | J12: 0 | K12: 0 | L12: 0 | M12: 0 | N12: 0 | O12: 0 | P12: 0 | Q12: 0 | R12: 0 | S12: 0 | T12: 0 | U12: 0 | V12: 0 | W12: 0 | X12: 0 | Y12: 0 | Z12: 0 | AA12: 0 | AB12: 0 | AC12: 0 | AD12: 0 | AE12: 0 | AF12: 0 | AG12: 0 | AH12: 0 | AI12: 0 | AJ12: 0 | AK12: 0 | AL12: 0 | AM12: 0 | AN12: 0 | AO12: 0 | AP12: 0 | AQ12: 0 | AR12: 0 | AS12: 0 | AT12: 0 | AU12: 0 | AV12: 0 | AW12: 0 | AX12: 0 | AY12: 0 | AZ12: 0 | BA12: 0 | BB12: 0 | BC12: 0 | BD12: 0 | BE12: 0 | BF12: 0 | BG12: 0 | BH12: 0 | BI12: 0 | BJ12: 0 | BK12: 0 | BL12: 0 | BM12: 0 | BN12: 0 | BO12: 0 | BP12: 0 | BQ12: 0 | BR12: 0 | BS12: 0 | BT12: 0 | BU12: 0 | BV12: 0 | BW12: 0 | BX12: 0 | BY12: 0 | BZ12: 0 | CA12: 0 | CB12: 0 | CC12: 0 | CD12: 0 | CE12: 0 | CF12: 0 | CG12: 0 | CH12: 0 | CI12: 0 | CJ12: 0 | CK12: 0 | CL12: 0 | CM12: 0 | CN12: 0 | CO12: 0 | CP12: =SUM(B12:CO12) -> 0
A13: C103ES | B13: 0 | C13: 0 | D13: 0 | E13: 0 | F13: 0 | G13: 0 | H13: 0 | I13: 0 | J13: 0 | K13: 0 | L13: 0 | M13: 0 | N13: 0 | O13: 0 | P13: 0 | Q13: 0 | R13: 0 | S13: 0 | T13: 0 | U13: 0 | V13: 0 | W13: 0 | X13: 0 | Y13: 0 | Z13: 0 | AA13: 0 | AB13: 0 | AC13: 0 | AD13: 0 | AE13: 0 | AF13: 0 | AG13: 0 | AH13: 0 | AI13: 0 | AJ13: 0 | AK13: 0 | AL13: 0 | AM13: 0 | AN13: 0 | AO13: 0 | AP13: 0 | AQ13: 0 | AR13: 0 | AS13: 0 | AT13: 0 | AU13: 0 | AV13: 0 | AW13: 0 | AX13: 0 | AY13: 0 | AZ13: 0 | BA13: 0 | BB13: 0 | BC13: 0 | BD13: 0 | BE13: 0 | BF13: 0 | BG13: 0 | BH13: 0 | BI13: 0 | BJ13: 0 | BK13: 0 | BL13: 0 | BM13: 0 | BN13: 0 | BO13: 0 | BP13: 0 | BQ13: 0 | BR13: 0 | BS13: 0 | BT13: 0 | BU13: 0 | BV13: 0 | BW13: 0 | BX13: 0 | BY13: 0 | BZ13: 0 | CA13: 0 | CB13: 0 | CC13: 0 | CD13: 0 | CE13: 0 | CF13: 0 | CG13: 0 | CH13: 0 | CI13: 0 | CJ13: 0 | CK13: 0 | CL13: 0 | CM13: 0 | CN13: 0 | CO13: 0 | CP13: =SUM(B13:CO13) -> 0
A14: C104 | B14: 0 | C14: 0 | D14: 0 | E14: 0 | F14: 0 | G14: 0 | H14: 0 | I14: 0 | J14: 1 | K14: 0 | L14: 0 | M14: 0 | N14: 0 | O14: 0 | P14: 0 | Q14: 0 | R14: 0 | S14: 0 | T14: 0 | U14: 0 | V14: 0 | W14: 0 | X14: 0 | Y14: 0 | Z14: 0 | AA14: 0 | AB14: 0 | AC14: 0 | AD14: 0 | AE14: 0 | AF14: 0 | AG14: 0 | AH14: 0 | AI14: 0 | AJ14: 0 | AK14: 0 | AL14: 0 | AM14: 0 | AN14: 0 | AO14: 0 | AP14: 0 | AQ14: 0 | AR14: 0 | AS14: 0 | AT14: 0 | AU14: 0 | AV14: 0 | AW14: 0 | AX14: 0 | AY14: 0 | AZ14: 0 | BA14: 0 | BB14: 0 | BC14: 0 | BD14: 0 | BE14: 0 | BF14: 0 | BG14: 0 | BH14: 0 | BI14: 0 | BJ14: 0 | BK14: 0 | BL14: 0 | BM14: 0 | BN14: 0 | BO14: 0 | BP14: 0 | BQ14: 0 | BR14: 0 | BS14: 0 | BT14: 0 | BU14: 0 | BV14: 0 | BW14: 0 | BX14: 0 | BY14: 0 | BZ14: 0 | CA14: 0 | CB14: 0 | CC14: 0 | CD14: 0 | CE14: 0 | CF14: 0 | CG14: 0 | CH14: 0 | CI14: 0 | CJ14: 0 | CK14: 0 | CL14: 0 | CM14: 0 | CN14: 0 | CO14: 0 | CP14: =SUM(B14:CO14) -> 1
A15: C105 | B15: 0 | C15: 0 | D15: 0 | E15: 0 | F15: 0 | G15: 0 | H15: 0 | I15: 0 | J15: 0 | K15: 0 | L15: 0 | M15: 0 | N15: 0 | O15: 0 | P15: 0 | Q15: 0 | R15: 0 | S15: 0 | T15: 0 | U15: 0 | V15: 0 | W15: 0 | X15: 0 | Y15: 0 | Z15: 0 | AA15: 0 | AB15: 0 | AC15: 0 | AD15: 0 | AE15: 0 | AF15: 0 | AG15: 0 | AH15: 0 | AI15: 0 | AJ15: 0 | AK15: 0 | AL15: 0 | AM15: 0 | AN15: 0 | AO15: 0 | AP15: 0 | AQ15: 0 | AR15: 0 | AS15: 0 | AT15: 0 | AU15: 0 | AV15: 0 | AW15: 0 | AX15: 0 | AY15: 0 | AZ15: 0 | BA15: 0 | BB15: 0 | BC15: 0 | BD15: 0 | BE15: 0 | BF15: 0 | BG15: 0 | BH15: 0 | BI15: 0 | BJ15: 0 | BK15: 0 | BL15: 0 | BM15: 0 | BN15: 0 | BO15: 0 | BP15: 0 | BQ15: 0 | BR15: 0 | BS15: 0 | BT15: 0 | BU15: 0 | BV15: 0 | BW15: 0 | BX15: 0 | BY15: 0 | BZ15: 0 | CA15: 0 | CB15: 0 | CC15: 0 | CD15: 0 | CE15: 0 | CF15: 0 | CG15: 0 | CH15: 0 | CI15: 0 | CJ15: 0 | CK15: 0 | CL15: 1 | CM15: 0 | CN15: 0 | CO15: 0 | CP15: =SUM(B15:CO15) -> 1
A16: C105ES | B16: 0 | C16: 0 | D16: 0 | E16: 0 | F16: 0 | G16: 0 | H16: 0 | I16: 0 | J16: 0 | K16: 0 | L16: 0 | M16: 0 | N16: 0 | O16: 0 | P16: 0 | Q16: 0 | R16: 0 | S16: 0 | T16: 0 | U16: 0 | V16: 0 | W16: 0 | X16: 0 | Y16: 0 | Z16: 0 | AA16: 0 | AB16: 0 | AC16: 0 | AD16: 0 | AE16: 0 | AF16: 0 | AG16: 0 | AH16: 0 | AI16: 0 | AJ16: 0 | AK16: 0 | AL16: 0 | AM16: 0 | AN16: 0 | AO16: 0 | AP16: 0 | AQ16: 0 | AR16: 0 | AS16: 0 | AT16: 0 | AU16: 0 | AV16: 0 | AW16: 0 | AX16: 0 | AY16: 0 | AZ16: 0 | BA16: 0 | BB16: 0 | BC16: 0 | BD16: 0 | BE16: 0 | BF16: 0 | BG16: 0 | BH16: 0 | BI16: 0 | BJ16: 0 | BK16: 0 | BL16: 0 | BM16: 0 | BN16: 0 | BO16: 0 | BP16: 0 | BQ16: 0 | BR16: 0 | BS16: 0 | BT16: 0 | BU16: 0 | BV16: 0 | BW16: 0 | BX16: 0 | BY16: 0 | BZ16: 0 | CA16: 0 | CB16: 0 | CC16: 0 | CD16: 0 | CE16: 0 | CF16: 0 | CG16: 0 | CH16: 0 | CI16: 0 | CJ16: 0 | CK16: 0 | CL16: 0 | CM16: 0 | CN16: 0 | CO16: 0 | CP16: =SUM(B16:CO16) -> 0
... A177: XES | B177: 0 | C177: 0 | D177: 0 | E177: 0 | F177: 0 | G177: 0 | H177: 0 | I177: 0 | J177: 0 | K177: 0 | L177: 0 | M177: 0 | N177: 0 | O177: 0 | P177: 0 | Q177: 0 | R177: 0 | S177: 0 | T177: 0 | U177: 0 | V177: 0 | W177: 0 | X177: 0 | Y177: 0 | Z177: 0 | AA177: 0 | AB177: 0 | AC177: 0 | AD177: 0 | AE177: 0 | AF177: 0 | AG177: 0 | AH177: 0 | AI177: 0 | AJ177: 0 | AK177: 0 | AL177: 0 | AM177: 0 | AN177: 0 | AO177: 0 | AP177: 0 | AQ177: 0 | AR177: 0 | AS177: 0 | AT177: 0 | AU177: 0 | AV177: 0 | AW177: 0 | AX177: 0 | AY177: 0 | AZ177: 0 | BA177: 0 | BB177: 0 | BC177: 0 | BD177: 0 | BE177: 0 | BF177: 0 | BG177: 0 | BH177: 0 | BI177: 0 | BJ177: 0 | BK177: 0 | BL177: 0 | BM177: 0 | BN177: 0 | BO177: 0 | BP177: 0 | BQ177: 0 | BR177: 0 | BS177: 0 | BT177: 0 | BU177: 0 | BV177: 0 | BW177: 0 | BX177: 0 | BY177: 0 | BZ177: 0 | CA177: 0 | CB177: 0 | CC177: 0 | CD177: 0 | CE177: 0 | CF177: 0 | CG177: 0 | CH177: 0 | CI177: 0 | CJ177: 0 | CK177: 0 | CL177: 0 | CM177: 0 | CN177: 0 | CO177: 0 | CP177: =SUM(B177:CO177) -> 0
A178: TOTAL | B178: =SUM(B5:B177) -> 0 | C178: =SUM(C5:C177) -> 12 | D178: =SUM(D5:D177) -> 11 | E178: =SUM(E5:E177) -> 0 | F178: =SUM(F5:F177) -> 0 | G178: =SUM(G5:G177) -> 6 | H178: =SUM(H5:H177) -> 0 | I178: =SUM(I5:I177) -> 1 | ... CP178: =SUM(CP5:CP177) -> 3083

Sheet Downtime
A1: Queenstown International Airport - GlideView Reports
A2: Downtime Week Ending Sunday, 25 October 2026
A4: Tag Name | B4: Description | C4: Faults | D4: Max Outage | E4: Mean Outage | F4: Downtime | G4: Time Faulted | H4: Time Restored
A5: C104PC_F | B5: Conveyor Cascade PE Fault | C5: 1 | D5: 00:00:00:15 | E5: 00:00:00:15 | F5: 00:00:00:15
F6: 00:00:00:15 | G6: 24/10/2026 6:57:50 AM | H6: 24/10/2026 6:58:05 AM
A7: C107PC_F | B7: Conveyor Cascade PE Fault | C7: 1 | D7: 00:00:03:09 | E7: 00:00:03:09 | F7: 00:00:03:09
F8: 00:00:03:09 | G8: 22/10/2026 11:37:03 AM | H8: 22/10/2026 11:40:12 AM
A9: C109ABD_INTRUSION_F | B9: Intrusion Fault | C9: 2 | D9: 00:00:00:45 | E9: 00:00:00:35 | F9: 00:00:01:10
F10: 00:00:00:45 | G10: 23/10/2026 3:11:16 PM | H10: 23/10/2026 3:12:01 PM
F11: 00:00:00:25 | G11: 24/10/2026 3:22:09 PM | H11: 24/10/2026 3:22:34 PM
A12: C109ABD_NOTAVAILABLE_F | B12: Not Available Fault | C12: 1 | D12: 00:00:01:41 | E12: 00:00:01:41 | F12: 00:00:01:41
F13: 00:00:01:41 | G13: 21/10/2026 6:47:49 AM | H13: 21/10/2026 6:49:30 AM
A14: C111ABD_INTRUSION_F | B14: Intrusion Fault | C14: 4 | D14: 00:00:01:06 | E14: 00:00:00:27 | F14: 00:00:01:48
F15: 00:00:00:08 | G15: 20/10/2026 11:53:05 AM | H15: 20/10/2026 11:53:13 AM
F16: 00:00:00:16 | G16: 20/10/2026 12:21:15 PM | H16: 20/10/2026 12:21:31 PM
F17: 00:00:01:06 | G17: 23/10/2026 12:24:02 PM | H17: 23/10/2026 12:25:08 PM
F18: 00:00:00:18 | G18: 23/10/2026 3:49:44 PM | H18: 23/10/2026 3:50:02 PM
A19: C111ABD_NOTAVAILABLE_F | B19: Not Available Fault | C19: 1 | D19: 00:00:01:24 | E19: 00:00:01:24 | F19: 00:00:01:24
F20: 00:00:01:24 | G20: 21/10/2026 6:50:07 AM | H20: 21/10/2026 6:51:31 AM
A21: C113ABD_INTRUSION_F | B21: ABD Intrusion Fault | C21: 3 | D21: 00:00:00:07 | E21: 00:00:00:04 | F21: 00:00:00:13
F22: 00:00:00:07 | G22: 23/10/2026 4:09:05 PM | H22: 23/10/2026 4:09:12 PM
F23: 00:00:00:03 | G23: 24/10/2026 11:39:29 AM | H23: 24/10/2026 11:39:32 AM
F24: 00:00:00:03 | G24: 24/10/2026 11:50:42 AM | H24: 24/10/2026 11:50:45 AM
A25: C113ABD_NOTAVAILABLE_F | B25: ABD Not Available Fault | C25: 4 | D25: 00:00:03:34 | E25: 00:00:02:28 | F25: 00:00:09:51
F26: 00:00:02:55 | G26: 19/10/2026 3:23:50 PM | H26: 19/10/2026 3:26:45 PM
F27: 00:00:01:45 | G27: 21/10/2026 6:54:25 AM | H27: 21/10/2026 6:56:10 AM
F28: 00:00:03:34 | G28: 21/10/2026 2:39:50 PM | H28: 21/10/2026 2:43:24 PM
F29: 00:00:01:37 | G29: 21/10/2026 5:47:37 PM | H29: 21/10/2026 5:49:14 PM
A30: C115ABD_INTRUSION_F | B30: ABD Intrusion Fault | C30: 2 | D30: 00:00:01:18 | E30: 00:00:00:41 | F30: 00:00:01:21
F31: 00:00:00:03 | G31: 19/10/2026 11:22:21 AM | H31: 19/10/2026 11:22:24 AM
F32: 00:00:01:18 | G32: 22/10/2026 12:49:30 PM | H32: 22/10/2026 12:50:48 PM
A33: C115ABD_NOTAVAILABLE_F | B33: ABD Not Available Fault | C33: 2 | D33: 00:00:02:12 | E33: 00:00:02:04 | F33: 00:00:04:08
F34: 00:00:01:56 | G34: 21/10/2026 6:58:05 AM | H34: 21/10/2026 7:00:01 AM
F35: 00:00:02:12 | G35: 21/10/2026 7:06:23 AM | H35: 21/10/2026 7:08:35 AM
A36: C117ABD_INTRUSION_F | B36: ABD Intrusion Fault | C36: 1 | D36: 00:00:02:01 | E36: 00:00:02:01 | F36: 00:00:02:01
F37: 00:00:02:01 | G37: 19/10/2026 8:53:28 AM | H37: 19/10/2026 8:55:29 AM
A38: C117ABD_NOTAVAILABLE_F | B38: ABD Not Available Fault | C38: 1 | D38: 00:00:01:53 | E38: 00:00:01:53 | F38: 00:00:01:53
F39: 00:00:01:53 | G39: 21/10/2026 6:58:47 AM | H39: 21/10/2026 7:00:40 AM
A40: C119ABD_INTRUSION_F | B40: ABD Intrusion Fault | C40: 4 | D40: 00:00:01:05 | E40: 00:00:00:23 | F40: 00:00:01:30
F41: 00:00:01:05 | G41: 22/10/2026 11:36:03 AM | H41: 22/10/2026 11:37:08 AM
...

Sheet System Throughput Rates
A1: Queenstown International Airport - GlideView Reports
A2: System Throughput Rates Week Ending Sunday, 25 October 2026
A4: UTCTime | B4: LocalTime | C4: DESK01 | D4: DESK02 | E4: DESK03 | F4: DESK04 | G4: DESK05 | H4: DESK06 | I4: DESK07 | J4: DESK08 | K4: DESK09 | L4: DESK10 | M4: DESK11 | N4: DESK12 | O4: DESK13 | P4: DESK14 | Q4: DESK15 | R4: DESK16 | S4: DESK17 | T4: DESK18 | U4: DESK19 | V4: DESK20 | W4: DESK21 | X4: DESK22 | Y4: MU1_RECIRC | Z4: OS104 | AA4: T101 | AB4: T114
A5: 46313.462 | B5: 46314.003 | C5: 0 | D5: 0 | E5: 0 | F5: 0 | G5: 0 | H5: 0 | I5: 0 | J5: 0 | K5: 0 | L5: 0 | M5: 0 | N5: 0 | O5: 0 | P5: 0 | Q5: 0 | R5: 0 | S5: 0 | T5: 0 | U5: 0 | V5: 0 | W5: 0 | X5: 0 | Y5: 0 | Z5: 0 | AA5: 0 | AB5: 0
A6: 46313.465 | B6: 46314.007 | C6: 0 | D6: 0 | E6: 0 | F6: 0 | G6: 0 | H6: 0 | I6: 0 | J6: 0 | K6: 0 | L6: 0 | M6: 0 | N6: 0 | O6: 0 | P6: 0 | Q6: 0 | R6: 0 | S6: 0 | T6: 0 | U6: 0 | V6: 0 | W6: 0 | X6: 0 | Y6: 0 | Z6: 0 | AA6: 0 | AB6: 0
A7: 46313.469 | B7: 46314.01 | C7: 0 | D7: 0 | E7: 0 | F7: 0 | G7: 0 | H7: 0 | I7: 0 | J7: 0 | K7: 0 | L7: 0 | M7: 0 | N7: 0 | O7: 0 | P7: 0 | Q7: 0 | R7: 0 | S7: 0 | T7: 0 | U7: 0 | V7: 0 | W7: 0 | X7: 0 | Y7: 0 | Z7: 0 | AA7: 0 | AB7: 0
A8: 46313.472 | B8: 46314.014 | C8: 0 | D8: 0 | E8: 0 | F8: 0 | G8: 0 | H8: 0 | I8: 0 | J8: 0 | K8: 0 | L8: 0 | M8: 0 | N8: 0 | O8: 0 | P8: 0 | Q8: 0 | R8: 0 | S8: 0 | T8: 0 | U8: 0 | V8: 0 | W8: 0 | X8: 0 | Y8: 0 | Z8: 0 | AA8: 0 | AB8: 0
A9: 46313.476 | B9: 46314.017 | C9: 0 | D9: 0 | E9: 0 | F9: 0 | G9: 0 | H9: 0 | I9: 0 | J9: 0 | K9: 0 | L9: 0 | M9: 0 | N9: 0 | O9: 0 | P9: 0 | Q9: 0 | R9: 0 | S9: 0 | T9: 0 | U9: 0 | V9: 0 | W9: 0 | X9: 0 | Y9: 0 | Z9: 0 | AA9: 0 | AB9: 0
A10: 46313.479 | B10: 46314.021 | C10: 0 | D10: 0 | E10: 0 | F10: 0 | G10: 0 | H10: 0 | I10: 0 | J10: 0 | K10: 0 | L10: 0 | M10: 0 | N10: 0 | O10: 0 | P10: 0 | Q10: 0 | R10: 0 | S10: 0 | T10: 0 | U10: 0 | V10: 0 | W10: 0 | X10: 0 | Y10: 0 | Z10: 0 | AA10: 0 | AB10: 0
A11: 46313.483 | B11: 46314.024 | C11: 0 | D11: 0 | E11: 0 | F11: 0 | G11: 0 | H11: 0 | I11: 0 | J11: 0 | K11: 0 | L11: 0 | M11: 0 | N11: 0 | O11: 0 | P11: 0 | Q11: 0 | R11: 0 | S11: 0 | T11: 0 | U11: 0 | V11: 0 | W11: 0 | X11: 0 | Y11: 0 | Z11: 0 | AA11: 0 | AB11: 0
A12: 46313.486 | B12: 46314.028 | C12: 0 | D12: 0 | E12: 0 | F12: 0 | G12: 0 | H12: 0 | I12: 0 | J12: 0 | K12: 0 | L12: 0 | M12: 0 | N12: 0 | O12: 0 | P12: 0 | Q12: 0 | R12: 0 | S12: 0 | T12: 0 | U12: 0 | V12: 0 | W12: 0 | X12: 0 | Y12: 0 | Z12: 0 | AA12: 0 | AB12: 0
A13: 46313.49 | B13: 46314.031 | C13: 0 | D13: 0 | E13: 0 | F13: 0 | G13: 0 | H13: 0 | I13: 0 | J13: 0 | K13: 0 | L13: 0 | M13: 0 | N13: 0 | O13: 0 | P13: 0 | Q13: 0 | R13: 0 | S13: 0 | T13: 0 | U13: 0 | V13: 0 | W13: 0 | X13: 0 | Y13: 0 | Z13: 0 | AA13: 0 | AB13: 0
A14: 46313.493 | B14: 46314.035 | C14: 0 | D14: 0 | E14: 0 | F14: 0 | G14: 0 | H14: 0 | I14: 0 | J14: 0 | K14: 0 | L14: 0 | M14: 0 | N14: 0 | O14: 0 | P14: 0 | Q14: 0 | R14: 0 | S14: 0 | T14: 0 | U14: 0 | V14: 0 | W14: 0 | X14: 0 | Y14: 0 | Z14: 0 | AA14: 0 | AB14: 0
A15: 46313.497 | B15: 46314.038 | C15: 0 | D15: 0 | E15: 0 | F15: 0 | G15: 0 | H15: 0 | I15: 0 | J15: 0 | K15: 0 | L15: 0 | M15: 0 | N15: 0 | O15: 0 | P15: 0 | Q15: 0 | R15: 0 | S15: 0 | T15: 0 | U15: 0 | V15: 0 | W15: 0 | X15: 0 | Y15: 0 | Z15: 0 | AA15: 0 | AB15: 0
A16: 46313.5 | B16: 46314.042 | C16: 0 | D16: 0 | E16: 0 | F16: 0 | G16: 0 | H16: 0 | I16: 0 | J16: 0 | K16: 0 | L16: 0 | M16: 0 | N16: 0 | O16: 0 | P16: 0 | Q16: 0 | R16: 0 | S16: 0 | T16: 0 | U16: 0 | V16: 0 | W16: 0 | X16: 0 | Y16: 0 | Z16: 0 | AA16: 0 | AB16: 0
... A2020: 46320.458 | B2020: 46321 | C2020: 0 | D2020: 0 | E2020: 0 | F2020: 0 | G2020: 0 | H2020: 0 | I2020: 0 | J2020: 0 | K2020: 0 | L2020: 0 | M2020: 0 | N2020: 0 | O2020: 0 | P2020: 0 | Q2020: 0 | R2020: 0 | S2020: 0 | T2020: 0 | U2020: 0 | V2020: 0 | W2020: 0 | X2020: 0 | Y2020: 0 | Z2020: 0 | AA2020: 0 | AB2020: 0

Sheet SUMMARY
A1: Queenstown International Airport - GlideView Reports
A2: =CONCATENATE("Summary Report ",MID('Throughput Statistics'!A2,23,100)) -> Summary Report Week Ending Sunday, 25 October 2026
A4: Throughput Statistics
A5: Main Outbound System
A6: T101 | B6: ='Throughput Statistics'!B31 -> 20573
A7: T114 | B7: ='Throughput Statistics'!B32 -> 20551
A8: Oversize Outbound System
A9: OS104 | B9: ='Throughput Statistics'!B36 -> 1582
A11: Screening Statistics
A12: Level 1 EDS Decisions
A13: L1 Clear Count | B13: ='Security Screening Statistics'!B7 -> 12412
A14: L1 Reject Bag Count | B14: ='Security Screening Statistics'!C7 -> 7240
A15: L1 No Scan Count | B15: ='Security Screening Statistics'!D7 -> 55
A16: L1 Timeout Count | B16: ='Security Screening Statistics'!E7 -> 0
A18: Level 2 EDS Decisions
A19: L2 Clear Count | B19: ='Security Screening Statistics'!B12 -> 6574
A20: L2 Reject Bag Count | B20: ='Security Screening Statistics'!C12 -> 507
A21: L2 Timeout Count | B21: ='Security Screening Statistics'!D12 -> 157
A23: Tracking Statistics
A24: Zone | B24: Tracked Bag Count | C24: Lost Bag Count
A25: T109PC | B25: ='Tracking Statistics'!B7 -> 0 | C25: ='Tracking Statistics'!C7 -> 0
A26: T110PC | B26: ='Tracking Statistics'!B8 -> 19652 | C26: ='Tracking Statistics'!C8 -> 35
A27: T111PC | B27: ='Tracking Statistics'!B9 -> 19601 | C27: ='Tracking Statistics'!C9 -> 1
A28: T112PC | B28: ='Tracking Statistics'!B10 -> 19629 | C28: ='Tracking Statistics'!C10 -> 1
A29: T1DV1PD | B29: ='Tracking Statistics'!B11 -> 19633 | C29: ='Tracking Statistics'!C11 -> 11
A30: T1DV1PU | B30: ='Tracking Statistics'!B12 -> 18929 | C30: ='Tracking Statistics'!C12 -> 2
A31: T110APC | B31: ='Tracking Statistics'!B13 -> 19624 | C31: ='Tracking Statistics'!C13 -> 18
A32: TOTAL | C32: =SUM(C25:C31) -> 68
A34: Plough Statistics
A35: Pushed Bag Count | B35: ='Plough Statistics'!C7 -> 727
A36: Not Pushed Bag Count | B36: ='Plough Statistics'!D7 -> 18931
A38: Makeup Recirculation
A39: Recirculation Count | B39: ='Throughput Statistics'!B33 -> 19230
A41: Dieback | B41: Total Duration | C41: Event Count | D41: Average Duration
A42: C135 | B42: =IF(ISERROR(VLOOKUP(CONCATENATE($A42,"_DIEBACK"),Downtime!$A:$F,6,FALSE)),"00:00:00:00",VLOOKUP(CONCATENATE($A42,"_DIEBACK"),Downtime!$A:$F,6,FALSE)) -> 00:00:40:01 | C42: =IF(ISERROR(VLOOKUP(CONCATENATE($A42,"_DIEBACK"),Downtime!$A:$F,3,FALSE)),0,VLOOKUP(CONCATENATE($A42,"_DIEBACK"),Downtime!$A:$F,3,FALSE)) -> 193 | D42: =IF(ISERROR(VLOOKUP(CONCATENATE($A42,"_DIEBACK"),Downtime!$A:$F,5,FALSE)),"00:00:00:00",VLOOKUP(CONCATENATE($A42,"_DIEBACK"),Downtime!$A:$F,5,FALSE)) -> 00:00:00:12
A43: T104 | B43: =IF(ISERROR(VLOOKUP(CONCATENATE($A43,"_DIEBACK"),Downtime!$A:$F,6,FALSE)),"00:00:00:00",VLOOKUP(CONCATENATE($A43,"_DIEBACK"),Downtime!$A:$F,6,FALSE)) -> 00:02:36:36 | C43: =IF(ISERROR(VLOOKUP(CONCATENATE($A43,"_DIEBACK"),Downtime!$A:$F,3,FALSE)),0,VLOOKUP(CONCATENATE($A43,"_DIEBACK"),Downtime!$A:$F,3,FALSE)) -> 1992 | D43: =IF(ISERROR(VLOOKUP(CONCATENATE($A43,"_DIEBACK"),Downtime!$A:$F,5,FALSE)),"00:00:00:00",VLOOKUP(CONCATENATE($A43,"_DIEBACK"),Downtime!$A:$F,5,FALSE)) -> 00:00:00:05
A44: T119 | B44: =IF(ISERROR(VLOOKUP(CONCATENATE($A44,"_DIEBACK"),Downtime!$A:$F,6,FALSE)),"00:00:00:00",VLOOKUP(CONCATENATE($A44,"_DIEBACK"),Downtime!$A:$F,6,FALSE)) -> 00:01:21:58 | C44: =IF(ISERROR(VLOOKUP(CONCATENATE($A44,"_DIEBACK"),Downtime!$A:$F,3,FALSE)),0,VLOOKUP(CONCATENATE($A44,"_DIEBACK"),Downtime!$A:$F,3,FALSE)) -> 677 | D44: =IF(ISERROR(VLOOKUP(CONCATENATE($A44,"_DIEBACK"),Downtime!$A:$F,5,FALSE)),"00:00:00:00",VLOOKUP(CONCATENATE($A44,"_DIEBACK"),Downtime!$A:$F,5,FALSE)) -> 00:00:00:07
